<?xml version="1.0" ?>
<robot xmlns:xacro="http://www.ros.org/wiki/xacro">

  <xacro:include filename="$(find pollen_generic_description)/urdf/inertial_primitives.urdf.xacro"/>
  <xacro:include filename="$(find pollen_generic_description)/urdf/materials.urdf.xacro"/>
  <xacro:include filename="$(find orbita2d_description)/ros2_control/orbita2d.ros2_control.xacro"/>


    <!-- <material name="orbita2dmetal"> -->
    <!--     <color rgba="0.85 0.85 0.85 1.0"/> -->
    <!-- </material> -->
    <!-- <material name="orbita2dgrey"> -->
    <!--     <color rgba="0.8 0.8 0.8 1.0"/> -->
    <!-- </material> -->

  <xacro:macro name="joint2axis" params="joint">
    <xacro:if value="${joint == 'roll'}">
      <axis xyz="1 0 0"/>
    </xacro:if>
    <xacro:if value="${joint == 'pitch'}">
      <axis xyz="0 0 1"/>
    </xacro:if>
    <xacro:if value="${joint == 'yaw'}">
      <axis xyz="0 1 0"/>
    </xacro:if>
  </xacro:macro>

  <xacro:macro name="orbita2d" params="name parent length radius mass xyz rpy damping friction joint1 joint2 joint1_min_angle joint1_max_angle joint2_min_angle joint2_max_angle config_file">

    <!--
      Orbita 2 dof

    link                      (joint)

    ${parent}                 (${name}_joint1)
      ${name}_first_link      (${name}_joint2)
        ${name}_link          (${name}_ball_joint)
          ${name}_ball_link
    -->



    <!-- used to "place" the joint with the correct axis. For some reason rotation of the inertia patrix does not work... -->
    <link name="${name}_dummy_link1">
    </link>

    <joint name="${name}_dummy_1" type="fixed">
      <origin xyz="${xyz}" rpy="${rpy}"/>
      <parent link="${parent}"/>
      <child link="${name}_dummy_link1"/>
    </joint>

    <link name="${name}_dummy_link2">
    </link>

    <joint name="${name}_dummy_2" type="fixed">
      <origin xyz="0 0 0" rpy="1.5707963267948966 0 0"/>
      <parent link="${name}_dummy_link1"/>
      <child link="${name}_dummy_link2"/>
    </joint>




    <link name="${name}_first_link">
      <visual>
      	<origin xyz="0 0 0" rpy="0 0 0"/>
      	<geometry>
	  <mesh filename="package://orbita2d_description/meshes/2D_sphere_visual.dae" />
	  <!-- <mesh filename="package://orbita2d_description/meshes/Orbita2D_Link.dae" /> -->
      	</geometry>

      </visual>

      <inertial>
      	<!-- <origin xyz="0.0 0 0" rpy="1.5707963267948966 0 0"/> -->  <!-- rotation does not work? -->
      	<origin xyz="0.000096 -0.000015 -0.01777" rpy="0 0 0"/>
	<mass value="0.487"/>
	 <inertia ixx="0.000577881945" ixy="-8.085000000000001e-7" ixz="-6.962790000000001e-7"
		  iyx="-8.085000000000001e-7" iyy="0.000573075516" iyz="2.44386e-7"
		  izx="-6.962790000000001e-7" izy="2.44386e-7" izz="0.000243343676"/>
      </inertial>

    </link>

    <!-- First joint  -->
    <joint name="${name}_${joint1}" type="revolute">
      <origin xyz="0 0 0" rpy="0 0 0"/>
      <!-- <parent link="${parent}"/> -->
      <parent link="${name}_dummy_link2"/>
      <child link="${name}_first_link"/>
      <xacro:joint2axis joint="${joint1}"/>
      <limit lower="${joint1_min_angle}" upper="${joint1_max_angle}" effort="1000.0" velocity="100.0"/>
      <safety_controller k_velocity="500" k_position="500" soft_lower_limit="-3.1415" soft_upper_limit="3.1415" />
      <dynamics damping="${damping}" friction="${friction}"/>
    </joint>



    <!-- Used to get back to the correct orientation -->
    <link name="${name}_dummy_link3">
    </link>

    <joint name="${name}_dummy_3" type="fixed">
      <origin xyz="0 0 0" rpy="-1.5707963267948966 0 0"/>
      <parent link="${name}_first_link"/>
      <child link="${name}_dummy_link3"/>
    </joint>



    <!-- Output link -->
    <link name="${name}_ball_link">
    </link>


    <joint name="${name}_${joint2}" type="revolute">
      <origin xyz="0 0 0" rpy=" 0 0 0"/>
      <parent link="${name}_dummy_link3"/>
      <child link="${name}_ball_link"/>
      <xacro:joint2axis joint="${joint2}"/>
      <limit lower="${joint2_min_angle}" upper="${joint2_max_angle}" effort="1000.0" velocity="100.0"/>
      <safety_controller k_velocity="500" k_position="500" soft_lower_limit="-3.1415" soft_upper_limit="3.1415" />
      <dynamics damping="${damping}" friction="${friction}"/>
    </joint>




    <xacro:orbita2d_control
      name="${name}"
      joint1="${joint1}" joint2="${joint2}"
      config_file="${config_file}"
    />



  </xacro:macro>
</robot>
